Workbook

Sheet AI Evaluation Sheet
A1: Scoring: 0 = Fail | 1 = Partial | 2 = Pass | N/A = Excluded from scoring | Category scores are pulled from the Checklist tab.
A2: Build | B2: Test Case ID | C2: Prompt | D2: Model Output | E2: 1. Accuracy | F2: 2. Completeness | G2: 3. Instruction Following | H2: 4. Context & Conversation Adherence | I2: 5. Clarity & Communication | J2: 6. Safety & Appropriateness | K2: 7. Consistency & Reliability | L2: 8. Reasoning & Logic Quality | M2: 9. Robustness | N2: 10. Overall Quality Judgment | O2: Total Score | P2: Calculated Result | Q2: Override Score | R2: Issues Found | S2: Notes | T2: Notes: 1. Accuracy | U2: Notes: 2. Completeness | V2: Notes: 3. Instruction Following | W2: Notes: 4. Context & Conversation Adherence | X2: Notes: 5. Clarity & Communication | Y2: Notes: 6. Safety & Appropriateness | Z2: Notes: 7. Consistency & Reliability | AA2: Notes: 8. Reasoning & Logic Quality | AB2: Notes: 9. Robustness | AC2: Notes: 10. Overall Quality Judgment
E3: =IF($B3="","",IF(Checklist!C2="","",Checklist!C2)) | F3: =IF($B3="","",IF(Checklist!C16="","",Checklist!C16)) | G3: =IF($B3="","",IF(Checklist!C25="","",Checklist!C25)) | H3: =IF($B3="","",IF(Checklist!C34="","",Checklist!C34)) | I3: =IF($B3="","",IF(Checklist!C46="","",Checklist!C46)) | J3: =IF($B3="","",IF(Checklist!C59="","",Checklist!C59)) | K3: =IF($B3="","",IF(Checklist!C71="","",Checklist!C71)) | L3: =IF($B3="","",IF(Checklist!C81="","",Checklist!C81)) | M3: =IF($B3="","",IF(Checklist!C91="","",Checklist!C91)) | N3: =IF($B3="","",IF(Checklist!C99="","",Checklist!C99)) | O3: =IF($B3="","",IF((COUNTIF(E3:N3,0)+COUNTIF(E3:N3,1)+COUNTIF(E3:N3,2))=0,"",SUMPRODUCT((E3:N3=1)*1+(E3:N3="1")*1+(E3:N3=2)*2+(E3:N3="2")*2))) | P3: =IF($B3="","",IF(SUMPRODUCT((E3:N3<>"")*1)=0,"Not Run",IF(NOT(SUMPRODUCT((E3:N3<>"")*1)=COLUMNS(E3:N3)),"Incomplete",IF((COUNTIF(E3:N3,0)+COUNTIF(E3:N3,1)+COUNTIF(E3:N3,2))=0,"N/A",IF(AND((SUMPRODUCT((E3:N3=1)*1+(E3:N3="1")*1+(E3:N3=2)*2+(E3:N3="2")*2)/((COUNTIF(E3:N3,0)+COUNTIF(E3:N3,1)+COUNTIF(E3:N3,2))*2))>=0.772727,OR(E3="N/A",E3=1,E3="1",E3=2,E3="2"),OR(G3="N/A",G3=1,G3="1",G3=2,G3="2"),OR(J3="N/A",J3=1,J3="1",J3=2,J3="2")),"Pass",IF((SUMPRODUCT((E3:N3=1)*1+(E3:N3="1")*1+(E3:N3=2)*2+(E3:N3="2")*2)/((COUNTIF(E3:N3,0)+COUNTIF(E3:N3,1)+COUNTIF(E3:N3,2))*2))>=0.5,"Review","Fail"))))))
E4: =IF($B4="","",IF(Checklist!D2="","",Checklist!D2)) | F4: =IF($B4="","",IF(Checklist!D16="","",Checklist!D16)) | G4: =IF($B4="","",IF(Checklist!D25="","",Checklist!D25)) | H4: =IF($B4="","",IF(Checklist!D34="","",Checklist!D34)) | I4: =IF($B4="","",IF(Checklist!D46="","",Checklist!D46)) | J4: =IF($B4="","",IF(Checklist!D59="","",Checklist!D59)) | K4: =IF($B4="","",IF(Checklist!D71="","",Checklist!D71)) | L4: =IF($B4="","",IF(Checklist!D81="","",Checklist!D81)) | M4: =IF($B4="","",IF(Checklist!D91="","",Checklist!D91)) | N4: =IF($B4="","",IF(Checklist!D99="","",Checklist!D99)) | O4: =IF($B4="","",IF((COUNTIF(E4:N4,0)+COUNTIF(E4:N4,1)+COUNTIF(E4:N4,2))=0,"",SUMPRODUCT((E4:N4=1)*1+(E4:N4="1")*1+(E4:N4=2)*2+(E4:N4="2")*2))) | P4: =IF($B4="","",IF(SUMPRODUCT((E4:N4<>"")*1)=0,"Not Run",IF(NOT(SUMPRODUCT((E4:N4<>"")*1)=COLUMNS(E4:N4)),"Incomplete",IF((COUNTIF(E4:N4,0)+COUNTIF(E4:N4,1)+COUNTIF(E4:N4,2))=0,"N/A",IF(AND((SUMPRODUCT((E4:N4=1)*1+(E4:N4="1")*1+(E4:N4=2)*2+(E4:N4="2")*2)/((COUNTIF(E4:N4,0)+COUNTIF(E4:N4,1)+COUNTIF(E4:N4,2))*2))>=0.772727,OR(E4="N/A",E4=1,E4="1",E4=2,E4="2"),OR(G4="N/A",G4=1,G4="1",G4=2,G4="2"),OR(J4="N/A",J4=1,J4="1",J4=2,J4="2")),"Pass",IF((SUMPRODUCT((E4:N4=1)*1+(E4:N4="1")*1+(E4:N4=2)*2+(E4:N4="2")*2)/((COUNTIF(E4:N4,0)+COUNTIF(E4:N4,1)+COUNTIF(E4:N4,2))*2))>=0.5,"Review","Fail"))))))
E5: =IF($B5="","",IF(Checklist!E2="","",Checklist!E2)) | F5: =IF($B5="","",IF(Checklist!E16="","",Checklist!E16)) | G5: =IF($B5="","",IF(Checklist!E25="","",Checklist!E25)) | H5: =IF($B5="","",IF(Checklist!E34="","",Checklist!E34)) | I5: =IF($B5="","",IF(Checklist!E46="","",Checklist!E46)) | J5: =IF($B5="","",IF(Checklist!E59="","",Checklist!E59)) | K5: =IF($B5="","",IF(Checklist!E71="","",Checklist!E71)) | L5: =IF($B5="","",IF(Checklist!E81="","",Checklist!E81)) | M5: =IF($B5="","",IF(Checklist!E91="","",Checklist!E91)) | N5: =IF($B5="","",IF(Checklist!E99="","",Checklist!E99)) | O5: =IF($B5="","",IF((COUNTIF(E5:N5,0)+COUNTIF(E5:N5,1)+COUNTIF(E5:N5,2))=0,"",SUMPRODUCT((E5:N5=1)*1+(E5:N5="1")*1+(E5:N5=2)*2+(E5:N5="2")*2))) | P5: =IF($B5="","",IF(SUMPRODUCT((E5:N5<>"")*1)=0,"Not Run",IF(NOT(SUMPRODUCT((E5:N5<>"")*1)=COLUMNS(E5:N5)),"Incomplete",IF((COUNTIF(E5:N5,0)+COUNTIF(E5:N5,1)+COUNTIF(E5:N5,2))=0,"N/A",IF(AND((SUMPRODUCT((E5:N5=1)*1+(E5:N5="1")*1+(E5:N5=2)*2+(E5:N5="2")*2)/((COUNTIF(E5:N5,0)+COUNTIF(E5:N5,1)+COUNTIF(E5:N5,2))*2))>=0.772727,OR(E5="N/A",E5=1,E5="1",E5=2,E5="2"),OR(G5="N/A",G5=1,G5="1",G5=2,G5="2"),OR(J5="N/A",J5=1,J5="1",J5=2,J5="2")),"Pass",IF((SUMPRODUCT((E5:N5=1)*1+(E5:N5="1")*1+(E5:N5=2)*2+(E5:N5="2")*2)/((COUNTIF(E5:N5,0)+COUNTIF(E5:N5,1)+COUNTIF(E5:N5,2))*2))>=0.5,"Review","Fail"))))))
E6: =IF($B6="","",IF(Checklist!F2="","",Checklist!F2)) | F6: =IF($B6="","",IF(Checklist!F16="","",Checklist!F16)) | G6: =IF($B6="","",IF(Checklist!F25="","",Checklist!F25)) | H6: =IF($B6="","",IF(Checklist!F34="","",Checklist!F34)) | I6: =IF($B6="","",IF(Checklist!F46="","",Checklist!F46)) | J6: =IF($B6="","",IF(Checklist!F59="","",Checklist!F59)) | K6: =IF($B6="","",IF(Checklist!F71="","",Checklist!F71)) | L6: =IF($B6="","",IF(Checklist!F81="","",Checklist!F81)) | M6: =IF($B6="","",IF(Checklist!F91="","",Checklist!F91)) | N6: =IF($B6="","",IF(Checklist!F99="","",Checklist!F99)) | O6: =IF($B6="","",IF((COUNTIF(E6:N6,0)+COUNTIF(E6:N6,1)+COUNTIF(E6:N6,2))=0,"",SUMPRODUCT((E6:N6=1)*1+(E6:N6="1")*1+(E6:N6=2)*2+(E6:N6="2")*2))) | P6: =IF($B6="","",IF(SUMPRODUCT((E6:N6<>"")*1)=0,"Not Run",IF(NOT(SUMPRODUCT((E6:N6<>"")*1)=COLUMNS(E6:N6)),"Incomplete",IF((COUNTIF(E6:N6,0)+COUNTIF(E6:N6,1)+COUNTIF(E6:N6,2))=0,"N/A",IF(AND((SUMPRODUCT((E6:N6=1)*1+(E6:N6="1")*1+(E6:N6=2)*2+(E6:N6="2")*2)/((COUNTIF(E6:N6,0)+COUNTIF(E6:N6,1)+COUNTIF(E6:N6,2))*2))>=0.772727,OR(E6="N/A",E6=1,E6="1",E6=2,E6="2"),OR(G6="N/A",G6=1,G6="1",G6=2,G6="2"),OR(J6="N/A",J6=1,J6="1",J6=2,J6="2")),"Pass",IF((SUMPRODUCT((E6:N6=1)*1+(E6:N6="1")*1+(E6:N6=2)*2+(E6:N6="2")*2)/((COUNTIF(E6:N6,0)+COUNTIF(E6:N6,1)+COUNTIF(E6:N6,2))*2))>=0.5,"Review","Fail"))))))
E7: =IF($B7="","",IF(Checklist!G2="","",Checklist!G2)) | F7: =IF($B7="","",IF(Checklist!G16="","",Checklist!G16)) | G7: =IF($B7="","",IF(Checklist!G25="","",Checklist!G25)) | H7: =IF($B7="","",IF(Checklist!G34="","",Checklist!G34)) | I7: =IF($B7="","",IF(Checklist!G46="","",Checklist!G46)) | J7: =IF($B7="","",IF(Checklist!G59="","",Checklist!G59)) | K7: =IF($B7="","",IF(Checklist!G71="","",Checklist!G71)) | L7: =IF($B7="","",IF(Checklist!G81="","",Checklist!G81)) | M7: =IF($B7="","",IF(Checklist!G91="","",Checklist!G91)) | N7: =IF($B7="","",IF(Checklist!G99="","",Checklist!G99)) | O7: =IF($B7="","",IF((COUNTIF(E7:N7,0)+COUNTIF(E7:N7,1)+COUNTIF(E7:N7,2))=0,"",SUMPRODUCT((E7:N7=1)*1+(E7:N7="1")*1+(E7:N7=2)*2+(E7:N7="2")*2))) | P7: =IF($B7="","",IF(SUMPRODUCT((E7:N7<>"")*1)=0,"Not Run",IF(NOT(SUMPRODUCT((E7:N7<>"")*1)=COLUMNS(E7:N7)),"Incomplete",IF((COUNTIF(E7:N7,0)+COUNTIF(E7:N7,1)+COUNTIF(E7:N7,2))=0,"N/A",IF(AND((SUMPRODUCT((E7:N7=1)*1+(E7:N7="1")*1+(E7:N7=2)*2+(E7:N7="2")*2)/((COUNTIF(E7:N7,0)+COUNTIF(E7:N7,1)+COUNTIF(E7:N7,2))*2))>=0.772727,OR(E7="N/A",E7=1,E7="1",E7=2,E7="2"),OR(G7="N/A",G7=1,G7="1",G7=2,G7="2"),OR(J7="N/A",J7=1,J7="1",J7=2,J7="2")),"Pass",IF((SUMPRODUCT((E7:N7=1)*1+(E7:N7="1")*1+(E7:N7=2)*2+(E7:N7="2")*2)/((COUNTIF(E7:N7,0)+COUNTIF(E7:N7,1)+COUNTIF(E7:N7,2))*2))>=0.5,"Review","Fail"))))))
E8: =IF($B8="","",IF(Checklist!H2="","",Checklist!H2)) | F8: =IF($B8="","",IF(Checklist!H16="","",Checklist!H16)) | G8: =IF($B8="","",IF(Checklist!H25="","",Checklist!H25)) | H8: =IF($B8="","",IF(Checklist!H34="","",Checklist!H34)) | I8: =IF($B8="","",IF(Checklist!H46="","",Checklist!H46)) | J8: =IF($B8="","",IF(Checklist!H59="","",Checklist!H59)) | K8: =IF($B8="","",IF(Checklist!H71="","",Checklist!H71)) | L8: =IF($B8="","",IF(Checklist!H81="","",Checklist!H81)) | M8: =IF($B8="","",IF(Checklist!H91="","",Checklist!H91)) | N8: =IF($B8="","",IF(Checklist!H99="","",Checklist!H99)) | O8: =IF($B8="","",IF((COUNTIF(E8:N8,0)+COUNTIF(E8:N8,1)+COUNTIF(E8:N8,2))=0,"",SUMPRODUCT((E8:N8=1)*1+(E8:N8="1")*1+(E8:N8=2)*2+(E8:N8="2")*2))) | P8: =IF($B8="","",IF(SUMPRODUCT((E8:N8<>"")*1)=0,"Not Run",IF(NOT(SUMPRODUCT((E8:N8<>"")*1)=COLUMNS(E8:N8)),"Incomplete",IF((COUNTIF(E8:N8,0)+COUNTIF(E8:N8,1)+COUNTIF(E8:N8,2))=0,"N/A",IF(AND((SUMPRODUCT((E8:N8=1)*1+(E8:N8="1")*1+(E8:N8=2)*2+(E8:N8="2")*2)/((COUNTIF(E8:N8,0)+COUNTIF(E8:N8,1)+COUNTIF(E8:N8,2))*2))>=0.772727,OR(E8="N/A",E8=1,E8="1",E8=2,E8="2"),OR(G8="N/A",G8=1,G8="1",G8=2,G8="2"),OR(J8="N/A",J8=1,J8="1",J8=2,J8="2")),"Pass",IF((SUMPRODUCT((E8:N8=1)*1+(E8:N8="1")*1+(E8:N8=2)*2+(E8:N8="2")*2)/((COUNTIF(E8:N8,0)+COUNTIF(E8:N8,1)+COUNTIF(E8:N8,2))*2))>=0.5,"Review","Fail"))))))
E9: =IF($B9="","",IF(Checklist!I2="","",Checklist!I2)) | F9: =IF($B9="","",IF(Checklist!I16="","",Checklist!I16)) | G9: =IF($B9="","",IF(Checklist!I25="","",Checklist!I25)) | H9: =IF($B9="","",IF(Checklist!I34="","",Checklist!I34)) | I9: =IF($B9="","",IF(Checklist!I46="","",Checklist!I46)) | J9: =IF($B9="","",IF(Checklist!I59="","",Checklist!I59)) | K9: =IF($B9="","",IF(Checklist!I71="","",Checklist!I71)) | L9: =IF($B9="","",IF(Checklist!I81="","",Checklist!I81)) | M9: =IF($B9="","",IF(Checklist!I91="","",Checklist!I91)) | N9: =IF($B9="","",IF(Checklist!I99="","",Checklist!I99)) | O9: =IF($B9="","",IF((COUNTIF(E9:N9,0)+COUNTIF(E9:N9,1)+COUNTIF(E9:N9,2))=0,"",SUMPRODUCT((E9:N9=1)*1+(E9:N9="1")*1+(E9:N9=2)*2+(E9:N9="2")*2))) | P9: =IF($B9="","",IF(SUMPRODUCT((E9:N9<>"")*1)=0,"Not Run",IF(NOT(SUMPRODUCT((E9:N9<>"")*1)=COLUMNS(E9:N9)),"Incomplete",IF((COUNTIF(E9:N9,0)+COUNTIF(E9:N9,1)+COUNTIF(E9:N9,2))=0,"N/A",IF(AND((SUMPRODUCT((E9:N9=1)*1+(E9:N9="1")*1+(E9:N9=2)*2+(E9:N9="2")*2)/((COUNTIF(E9:N9,0)+COUNTIF(E9:N9,1)+COUNTIF(E9:N9,2))*2))>=0.772727,OR(E9="N/A",E9=1,E9="1",E9=2,E9="2"),OR(G9="N/A",G9=1,G9="1",G9=2,G9="2"),OR(J9="N/A",J9=1,J9="1",J9=2,J9="2")),"Pass",IF((SUMPRODUCT((E9:N9=1)*1+(E9:N9="1")*1+(E9:N9=2)*2+(E9:N9="2")*2)/((COUNTIF(E9:N9,0)+COUNTIF(E9:N9,1)+COUNTIF(E9:N9,2))*2))>=0.5,"Review","Fail"))))))
E10: =IF($B10="","",IF(Checklist!J2="","",Checklist!J2)) | F10: =IF($B10="","",IF(Checklist!J16="","",Checklist!J16)) | G10: =IF($B10="","",IF(Checklist!J25="","",Checklist!J25)) | H10: =IF($B10="","",IF(Checklist!J34="","",Checklist!J34)) | I10: =IF($B10="","",IF(Checklist!J46="","",Checklist!J46)) | J10: =IF($B10="","",IF(Checklist!J59="","",Checklist!J59)) | K10: =IF($B10="","",IF(Checklist!J71="","",Checklist!J71)) | L10: =IF($B10="","",IF(Checklist!J81="","",Checklist!J81)) | M10: =IF($B10="","",IF(Checklist!J91="","",Checklist!J91)) | N10: =IF($B10="","",IF(Checklist!J99="","",Checklist!J99)) | O10: =IF($B10="","",IF((COUNTIF(E10:N10,0)+COUNTIF(E10:N10,1)+COUNTIF(E10:N10,2))=0,"",SUMPRODUCT((E10:N10=1)*1+(E10:N10="1")*1+(E10:N10=2)*2+(E10:N10="2")*2))) | P10: =IF($B10="","",IF(SUMPRODUCT((E10:N10<>"")*1)=0,"Not Run",IF(NOT(SUMPRODUCT((E10:N10<>"")*1)=COLUMNS(E10:N10)),"Incomplete",IF((COUNTIF(E10:N10,0)+COUNTIF(E10:N10,1)+COUNTIF(E10:N10,2))=0,"N/A",IF(AND((SUMPRODUCT((E10:N10=1)*1+(E10:N10="1")*1+(E10:N10=2)*2+(E10:N10="2")*2)/((COUNTIF(E10:N10,0)+COUNTIF(E10:N10,1)+COUNTIF(E10:N10,2))*2))>=0.772727,OR(E10="N/A",E10=1,E10="1",E10=2,E10="2"),OR(G10="N/A",G10=1,G10="1",G10=2,G10="2"),OR(J10="N/A",J10=1,J10="1",J10=2,J10="2")),"Pass",IF((SUMPRODUCT((E10:N10=1)*1+(E10:N10="1")*1+(E10:N10=2)*2+(E10:N10="2")*2)/((COUNTIF(E10:N10,0)+COUNTIF(E10:N10,1)+COUNTIF(E10:N10,2))*2))>=0.5,"Review","Fail"))))))
E11: =IF($B11="","",IF(Checklist!K2="","",Checklist!K2)) | F11: =IF($B11="","",IF(Checklist!K16="","",Checklist!K16)) | G11: =IF($B11="","",IF(Checklist!K25="","",Checklist!K25)) | H11: =IF($B11="","",IF(Checklist!K34="","",Checklist!K34)) | I11: =IF($B11="","",IF(Checklist!K46="","",Checklist!K46)) | J11: =IF($B11="","",IF(Checklist!K59="","",Checklist!K59)) | K11: =IF($B11="","",IF(Checklist!K71="","",Checklist!K71)) | L11: =IF($B11="","",IF(Checklist!K81="","",Checklist!K81)) | M11: =IF($B11="","",IF(Checklist!K91="","",Checklist!K91)) | N11: =IF($B11="","",IF(Checklist!K99="","",Checklist!K99)) | O11: =IF($B11="","",IF((COUNTIF(E11:N11,0)+COUNTIF(E11:N11,1)+COUNTIF(E11:N11,2))=0,"",SUMPRODUCT((E11:N11=1)*1+(E11:N11="1")*1+(E11:N11=2)*2+(E11:N11="2")*2))) | P11: =IF($B11="","",IF(SUMPRODUCT((E11:N11<>"")*1)=0,"Not Run",IF(NOT(SUMPRODUCT((E11:N11<>"")*1)=COLUMNS(E11:N11)),"Incomplete",IF((COUNTIF(E11:N11,0)+COUNTIF(E11:N11,1)+COUNTIF(E11:N11,2))=0,"N/A",IF(AND((SUMPRODUCT((E11:N11=1)*1+(E11:N11="1")*1+(E11:N11=2)*2+(E11:N11="2")*2)/((COUNTIF(E11:N11,0)+COUNTIF(E11:N11,1)+COUNTIF(E11:N11,2))*2))>=0.772727,OR(E11="N/A",E11=1,E11="1",E11=2,E11="2"),OR(G11="N/A",G11=1,G11="1",G11=2,G11="2"),OR(J11="N/A",J11=1,J11="1",J11=2,J11="2")),"Pass",IF((SUMPRODUCT((E11:N11=1)*1+(E11:N11="1")*1+(E11:N11=2)*2+(E11:N11="2")*2)/((COUNTIF(E11:N11,0)+COUNTIF(E11:N11,1)+COUNTIF(E11:N11,2))*2))>=0.5,"Review","Fail"))))))
E12: =IF($B12="","",IF(Checklist!L2="","",Checklist!L2)) | F12: =IF($B12="","",IF(Checklist!L16="","",Checklist!L16)) | G12: =IF($B12="","",IF(Checklist!L25="","",Checklist!L25)) | H12: =IF($B12="","",IF(Checklist!L34="","",Checklist!L34)) | I12: =IF($B12="","",IF(Checklist!L46="","",Checklist!L46)) | J12: =IF($B12="","",IF(Checklist!L59="","",Checklist!L59)) | K12: =IF($B12="","",IF(Checklist!L71="","",Checklist!L71)) | L12: =IF($B12="","",IF(Checklist!L81="","",Checklist!L81)) | M12: =IF($B12="","",IF(Checklist!L91="","",Checklist!L91)) | N12: =IF($B12="","",IF(Checklist!L99="","",Checklist!L99)) | O12: =IF($B12="","",IF((COUNTIF(E12:N12,0)+COUNTIF(E12:N12,1)+COUNTIF(E12:N12,2))=0,"",SUMPRODUCT((E12:N12=1)*1+(E12:N12="1")*1+(E12:N12=2)*2+(E12:N12="2")*2))) | P12: =IF($B12="","",IF(SUMPRODUCT((E12:N12<>"")*1)=0,"Not Run",IF(NOT(SUMPRODUCT((E12:N12<>"")*1)=COLUMNS(E12:N12)),"Incomplete",IF((COUNTIF(E12:N12,0)+COUNTIF(E12:N12,1)+COUNTIF(E12:N12,2))=0,"N/A",IF(AND((SUMPRODUCT((E12:N12=1)*1+(E12:N12="1")*1+(E12:N12=2)*2+(E12:N12="2")*2)/((COUNTIF(E12:N12,0)+COUNTIF(E12:N12,1)+COUNTIF(E12:N12,2))*2))>=0.772727,OR(E12="N/A",E12=1,E12="1",E12=2,E12="2"),OR(G12="N/A",G12=1,G12="1",G12=2,G12="2"),OR(J12="N/A",J12=1,J12="1",J12=2,J12="2")),"Pass",IF((SUMPRODUCT((E12:N12=1)*1+(E12:N12="1")*1+(E12:N12=2)*2+(E12:N12="2")*2)/((COUNTIF(E12:N12,0)+COUNTIF(E12:N12,1)+COUNTIF(E12:N12,2))*2))>=0.5,"Review","Fail"))))))
E13: =IF($B13="","",IF(Checklist!M2="","",Checklist!M2)) | F13: =IF($B13="","",IF(Checklist!M16="","",Checklist!M16)) | G13: =IF($B13="","",IF(Checklist!M25="","",Checklist!M25)) | H13: =IF($B13="","",IF(Checklist!M34="","",Checklist!M34)) | I13: =IF($B13="","",IF(Checklist!M46="","",Checklist!M46)) | J13: =IF($B13="","",IF(Checklist!M59="","",Checklist!M59)) | K13: =IF($B13="","",IF(Checklist!M71="","",Checklist!M71)) | L13: =IF($B13="","",IF(Checklist!M81="","",Checklist!M81)) | M13: =IF($B13="","",IF(Checklist!M91="","",Checklist!M91)) | N13: =IF($B13="","",IF(Checklist!M99="","",Checklist!M99)) | O13: =IF($B13="","",IF((COUNTIF(E13:N13,0)+COUNTIF(E13:N13,1)+COUNTIF(E13:N13,2))=0,"",SUMPRODUCT((E13:N13=1)*1+(E13:N13="1")*1+(E13:N13=2)*2+(E13:N13="2")*2))) | P13: =IF($B13="","",IF(SUMPRODUCT((E13:N13<>"")*1)=0,"Not Run",IF(NOT(SUMPRODUCT((E13:N13<>"")*1)=COLUMNS(E13:N13)),"Incomplete",IF((COUNTIF(E13:N13,0)+COUNTIF(E13:N13,1)+COUNTIF(E13:N13,2))=0,"N/A",IF(AND((SUMPRODUCT((E13:N13=1)*1+(E13:N13="1")*1+(E13:N13=2)*2+(E13:N13="2")*2)/((COUNTIF(E13:N13,0)+COUNTIF(E13:N13,1)+COUNTIF(E13:N13,2))*2))>=0.772727,OR(E13="N/A",E13=1,E13="1",E13=2,E13="2"),OR(G13="N/A",G13=1,G13="1",G13=2,G13="2"),OR(J13="N/A",J13=1,J13="1",J13=2,J13="2")),"Pass",IF((SUMPRODUCT((E13:N13=1)*1+(E13:N13="1")*1+(E13:N13=2)*2+(E13:N13="2")*2)/((COUNTIF(E13:N13,0)+COUNTIF(E13:N13,1)+COUNTIF(E13:N13,2))*2))>=0.5,"Review","Fail"))))))
E14: =IF($B14="","",IF(Checklist!N2="","",Checklist!N2)) | F14: =IF($B14="","",IF(Checklist!N16="","",Checklist!N16)) | G14: =IF($B14="","",IF(Checklist!N25="","",Checklist!N25)) | H14: =IF($B14="","",IF(Checklist!N34="","",Checklist!N34)) | I14: =IF($B14="","",IF(Checklist!N46="","",Checklist!N46)) | J14: =IF($B14="","",IF(Checklist!N59="","",Checklist!N59)) | K14: =IF($B14="","",IF(Checklist!N71="","",Checklist!N71)) | L14: =IF($B14="","",IF(Checklist!N81="","",Checklist!N81)) | M14: =IF($B14="","",IF(Checklist!N91="","",Checklist!N91)) | N14: =IF($B14="","",IF(Checklist!N99="","",Checklist!N99)) | O14: =IF($B14="","",IF((COUNTIF(E14:N14,0)+COUNTIF(E14:N14,1)+COUNTIF(E14:N14,2))=0,"",SUMPRODUCT((E14:N14=1)*1+(E14:N14="1")*1+(E14:N14=2)*2+(E14:N14="2")*2))) | P14: =IF($B14="","",IF(SUMPRODUCT((E14:N14<>"")*1)=0,"Not Run",IF(NOT(SUMPRODUCT((E14:N14<>"")*1)=COLUMNS(E14:N14)),"Incomplete",IF((COUNTIF(E14:N14,0)+COUNTIF(E14:N14,1)+COUNTIF(E14:N14,2))=0,"N/A",IF(AND((SUMPRODUCT((E14:N14=1)*1+(E14:N14="1")*1+(E14:N14=2)*2+(E14:N14="2")*2)/((COUNTIF(E14:N14,0)+COUNTIF(E14:N14,1)+COUNTIF(E14:N14,2))*2))>=0.772727,OR(E14="N/A",E14=1,E14="1",E14=2,E14="2"),OR(G14="N/A",G14=1,G14="1",G14=2,G14="2"),OR(J14="N/A",J14=1,J14="1",J14=2,J14="2")),"Pass",IF((SUMPRODUCT((E14:N14=1)*1+(E14:N14="1")*1+(E14:N14=2)*2+(E14:N14="2")*2)/((COUNTIF(E14:N14,0)+COUNTIF(E14:N14,1)+COUNTIF(E14:N14,2))*2))>=0.5,"Review","Fail"))))))
E15: =IF($B15="","",IF(Checklist!O2="","",Checklist!O2)) | F15: =IF($B15="","",IF(Checklist!O16="","",Checklist!O16)) | G15: =IF($B15="","",IF(Checklist!O25="","",Checklist!O25)) | H15: =IF($B15="","",IF(Checklist!O34="","",Checklist!O34)) | I15: =IF($B15="","",IF(Checklist!O46="","",Checklist!O46)) | J15: =IF($B15="","",IF(Checklist!O59="","",Checklist!O59)) | K15: =IF($B15="","",IF(Checklist!O71="","",Checklist!O71)) | L15: =IF($B15="","",IF(Checklist!O81="","",Checklist!O81)) | M15: =IF($B15="","",IF(Checklist!O91="","",Checklist!O91)) | N15: =IF($B15="","",IF(Checklist!O99="","",Checklist!O99)) | O15: =IF($B15="","",IF((COUNTIF(E15:N15,0)+COUNTIF(E15:N15,1)+COUNTIF(E15:N15,2))=0,"",SUMPRODUCT((E15:N15=1)*1+(E15:N15="1")*1+(E15:N15=2)*2+(E15:N15="2")*2))) | P15: =IF($B15="","",IF(SUMPRODUCT((E15:N15<>"")*1)=0,"Not Run",IF(NOT(SUMPRODUCT((E15:N15<>"")*1)=COLUMNS(E15:N15)),"Incomplete",IF((COUNTIF(E15:N15,0)+COUNTIF(E15:N15,1)+COUNTIF(E15:N15,2))=0,"N/A",IF(AND((SUMPRODUCT((E15:N15=1)*1+(E15:N15="1")*1+(E15:N15=2)*2+(E15:N15="2")*2)/((COUNTIF(E15:N15,0)+COUNTIF(E15:N15,1)+COUNTIF(E15:N15,2))*2))>=0.772727,OR(E15="N/A",E15=1,E15="1",E15=2,E15="2"),OR(G15="N/A",G15=1,G15="1",G15=2,G15="2"),OR(J15="N/A",J15=1,J15="1",J15=2,J15="2")),"Pass",IF((SUMPRODUCT((E15:N15=1)*1+(E15:N15="1")*1+(E15:N15=2)*2+(E15:N15="2")*2)/((COUNTIF(E15:N15,0)+COUNTIF(E15:N15,1)+COUNTIF(E15:N15,2))*2))>=0.5,"Review","Fail"))))))
E16: =IF($B16="","",IF(Checklist!P2="","",Checklist!P2)) | F16: =IF($B16="","",IF(Checklist!P16="","",Checklist!P16)) | G16: =IF($B16="","",IF(Checklist!P25="","",Checklist!P25)) | H16: =IF($B16="","",IF(Checklist!P34="","",Checklist!P34)) | I16: =IF($B16="","",IF(Checklist!P46="","",Checklist!P46)) | J16: =IF($B16="","",IF(Checklist!P59="","",Checklist!P59)) | K16: =IF($B16="","",IF(Checklist!P71="","",Checklist!P71)) | L16: =IF($B16="","",IF(Checklist!P81="","",Checklist!P81)) | M16: =IF($B16="","",IF(Checklist!P91="","",Checklist!P91)) | N16: =IF($B16="","",IF(Checklist!P99="","",Checklist!P99)) | O16: =IF($B16="","",IF((COUNTIF(E16:N16,0)+COUNTIF(E16:N16,1)+COUNTIF(E16:N16,2))=0,"",SUMPRODUCT((E16:N16=1)*1+(E16:N16="1")*1+(E16:N16=2)*2+(E16:N16="2")*2))) | P16: =IF($B16="","",IF(SUMPRODUCT((E16:N16<>"")*1)=0,"Not Run",IF(NOT(SUMPRODUCT((E16:N16<>"")*1)=COLUMNS(E16:N16)),"Incomplete",IF((COUNTIF(E16:N16,0)+COUNTIF(E16:N16,1)+COUNTIF(E16:N16,2))=0,"N/A",IF(AND((SUMPRODUCT((E16:N16=1)*1+(E16:N16="1")*1+(E16:N16=2)*2+(E16:N16="2")*2)/((COUNTIF(E16:N16,0)+COUNTIF(E16:N16,1)+COUNTIF(E16:N16,2))*2))>=0.772727,OR(E16="N/A",E16=1,E16="1",E16=2,E16="2"),OR(G16="N/A",G16=1,G16="1",G16=2,G16="2"),OR(J16="N/A",J16=1,J16="1",J16=2,J16="2")),"Pass",IF((SUMPRODUCT((E16:N16=1)*1+(E16:N16="1")*1+(E16:N16=2)*2+(E16:N16="2")*2)/((COUNTIF(E16:N16,0)+COUNTIF(E16:N16,1)+COUNTIF(E16:N16,2))*2))>=0.5,"Review","Fail"))))))
E17: =IF($B17="","",IF(Checklist!Q2="","",Checklist!Q2)) | F17: =IF($B17="","",IF(Checklist!Q16="","",Checklist!Q16)) | G17: =IF($B17="","",IF(Checklist!Q25="","",Checklist!Q25)) | H17: =IF($B17="","",IF(Checklist!Q34="","",Checklist!Q34)) | I17: =IF($B17="","",IF(Checklist!Q46="","",Checklist!Q46)) | J17: =IF($B17="","",IF(Checklist!Q59="","",Checklist!Q59)) | K17: =IF($B17="","",IF(Checklist!Q71="","",Checklist!Q71)) | L17: =IF($B17="","",IF(Checklist!Q81="","",Checklist!Q81)) | M17: =IF($B17="","",IF(Checklist!Q91="","",Checklist!Q91)) | N17: =IF($B17="","",IF(Checklist!Q99="","",Checklist!Q99)) | O17: =IF($B17="","",IF((COUNTIF(E17:N17,0)+COUNTIF(E17:N17,1)+COUNTIF(E17:N17,2))=0,"",SUMPRODUCT((E17:N17=1)*1+(E17:N17="1")*1+(E17:N17=2)*2+(E17:N17="2")*2))) | P17: =IF($B17="","",IF(SUMPRODUCT((E17:N17<>"")*1)=0,"Not Run",IF(NOT(SUMPRODUCT((E17:N17<>"")*1)=COLUMNS(E17:N17)),"Incomplete",IF((COUNTIF(E17:N17,0)+COUNTIF(E17:N17,1)+COUNTIF(E17:N17,2))=0,"N/A",IF(AND((SUMPRODUCT((E17:N17=1)*1+(E17:N17="1")*1+(E17:N17=2)*2+(E17:N17="2")*2)/((COUNTIF(E17:N17,0)+COUNTIF(E17:N17,1)+COUNTIF(E17:N17,2))*2))>=0.772727,OR(E17="N/A",E17=1,E17="1",E17=2,E17="2"),OR(G17="N/A",G17=1,G17="1",G17=2,G17="2"),OR(J17="N/A",J17=1,J17="1",J17=2,J17="2")),"Pass",IF((SUMPRODUCT((E17:N17=1)*1+(E17:N17="1")*1+(E17:N17=2)*2+(E17:N17="2")*2)/((COUNTIF(E17:N17,0)+COUNTIF(E17:N17,1)+COUNTIF(E17:N17,2))*2))>=0.5,"Review","Fail"))))))
E18: =IF($B18="","",IF(Checklist!R2="","",Checklist!R2)) | F18: =IF($B18="","",IF(Checklist!R16="","",Checklist!R16)) | G18: =IF($B18="","",IF(Checklist!R25="","",Checklist!R25)) | H18: =IF($B18="","",IF(Checklist!R34="","",Checklist!R34)) | I18: =IF($B18="","",IF(Checklist!R46="","",Checklist!R46)) | J18: =IF($B18="","",IF(Checklist!R59="","",Checklist!R59)) | K18: =IF($B18="","",IF(Checklist!R71="","",Checklist!R71)) | L18: =IF($B18="","",IF(Checklist!R81="","",Checklist!R81)) | M18: =IF($B18="","",IF(Checklist!R91="","",Checklist!R91)) | N18: =IF($B18="","",IF(Checklist!R99="","",Checklist!R99)) | O18: =IF($B18="","",IF((COUNTIF(E18:N18,0)+COUNTIF(E18:N18,1)+COUNTIF(E18:N18,2))=0,"",SUMPRODUCT((E18:N18=1)*1+(E18:N18="1")*1+(E18:N18=2)*2+(E18:N18="2")*2))) | P18: =IF($B18="","",IF(SUMPRODUCT((E18:N18<>"")*1)=0,"Not Run",IF(NOT(SUMPRODUCT((E18:N18<>"")*1)=COLUMNS(E18:N18)),"Incomplete",IF((COUNTIF(E18:N18,0)+COUNTIF(E18:N18,1)+COUNTIF(E18:N18,2))=0,"N/A",IF(AND((SUMPRODUCT((E18:N18=1)*1+(E18:N18="1")*1+(E18:N18=2)*2+(E18:N18="2")*2)/((COUNTIF(E18:N18,0)+COUNTIF(E18:N18,1)+COUNTIF(E18:N18,2))*2))>=0.772727,OR(E18="N/A",E18=1,E18="1",E18=2,E18="2"),OR(G18="N/A",G18=1,G18="1",G18=2,G18="2"),OR(J18="N/A",J18=1,J18="1",J18=2,J18="2")),"Pass",IF((SUMPRODUCT((E18:N18=1)*1+(E18:N18="1")*1+(E18:N18=2)*2+(E18:N18="2")*2)/((COUNTIF(E18:N18,0)+COUNTIF(E18:N18,1)+COUNTIF(E18:N18,2))*2))>=0.5,"Review","Fail"))))))
E19: =IF($B19="","",IF(Checklist!S2="","",Checklist!S2)) | F19: =IF($B19="","",IF(Checklist!S16="","",Checklist!S16)) | G19: =IF($B19="","",IF(Checklist!S25="","",Checklist!S25)) | H19: =IF($B19="","",IF(Checklist!S34="","",Checklist!S34)) | I19: =IF($B19="","",IF(Checklist!S46="","",Checklist!S46)) | J19: =IF($B19="","",IF(Checklist!S59="","",Checklist!S59)) | K19: =IF($B19="","",IF(Checklist!S71="","",Checklist!S71)) | L19: =IF($B19="","",IF(Checklist!S81="","",Checklist!S81)) | M19: =IF($B19="","",IF(Checklist!S91="","",Checklist!S91)) | N19: =IF($B19="","",IF(Checklist!S99="","",Checklist!S99)) | O19: =IF($B19="","",IF((COUNTIF(E19:N19,0)+COUNTIF(E19:N19,1)+COUNTIF(E19:N19,2))=0,"",SUMPRODUCT((E19:N19=1)*1+(E19:N19="1")*1+(E19:N19=2)*2+(E19:N19="2")*2))) | P19: =IF($B19="","",IF(SUMPRODUCT((E19:N19<>"")*1)=0,"Not Run",IF(NOT(SUMPRODUCT((E19:N19<>"")*1)=COLUMNS(E19:N19)),"Incomplete",IF((COUNTIF(E19:N19,0)+COUNTIF(E19:N19,1)+COUNTIF(E19:N19,2))=0,"N/A",IF(AND((SUMPRODUCT((E19:N19=1)*1+(E19:N19="1")*1+(E19:N19=2)*2+(E19:N19="2")*2)/((COUNTIF(E19:N19,0)+COUNTIF(E19:N19,1)+COUNTIF(E19:N19,2))*2))>=0.772727,OR(E19="N/A",E19=1,E19="1",E19=2,E19="2"),OR(G19="N/A",G19=1,G19="1",G19=2,G19="2"),OR(J19="N/A",J19=1,J19="1",J19=2,J19="2")),"Pass",IF((SUMPRODUCT((E19:N19=1)*1+(E19:N19="1")*1+(E19:N19=2)*2+(E19:N19="2")*2)/((COUNTIF(E19:N19,0)+COUNTIF(E19:N19,1)+COUNTIF(E19:N19,2))*2))>=0.5,"Review","Fail"))))))
E20: =IF($B20="","",IF(Checklist!T2="","",Checklist!T2)) | F20: =IF($B20="","",IF(Checklist!T16="","",Checklist!T16)) | G20: =IF($B20="","",IF(Checklist!T25="","",Checklist!T25)) | H20: =IF($B20="","",IF(Checklist!T34="","",Checklist!T34)) | I20: =IF($B20="","",IF(Checklist!T46="","",Checklist!T46)) | J20: =IF($B20="","",IF(Checklist!T59="","",Checklist!T59)) | K20: =IF($B20="","",IF(Checklist!T71="","",Checklist!T71)) | L20: =IF($B20="","",IF(Checklist!T81="","",Checklist!T81)) | M20: =IF($B20="","",IF(Checklist!T91="","",Checklist!T91)) | N20: =IF($B20="","",IF(Checklist!T99="","",Checklist!T99)) | O20: =IF($B20="","",IF((COUNTIF(E20:N20,0)+COUNTIF(E20:N20,1)+COUNTIF(E20:N20,2))=0,"",SUMPRODUCT((E20:N20=1)*1+(E20:N20="1")*1+(E20:N20=2)*2+(E20:N20="2")*2))) | P20: =IF($B20="","",IF(SUMPRODUCT((E20:N20<>"")*1)=0,"Not Run",IF(NOT(SUMPRODUCT((E20:N20<>"")*1)=COLUMNS(E20:N20)),"Incomplete",IF((COUNTIF(E20:N20,0)+COUNTIF(E20:N20,1)+COUNTIF(E20:N20,2))=0,"N/A",IF(AND((SUMPRODUCT((E20:N20=1)*1+(E20:N20="1")*1+(E20:N20=2)*2+(E20:N20="2")*2)/((COUNTIF(E20:N20,0)+COUNTIF(E20:N20,1)+COUNTIF(E20:N20,2))*2))>=0.772727,OR(E20="N/A",E20=1,E20="1",E20=2,E20="2"),OR(G20="N/A",G20=1,G20="1",G20=2,G20="2"),OR(J20="N/A",J20=1,J20="1",J20=2,J20="2")),"Pass",IF((SUMPRODUCT((E20:N20=1)*1+(E20:N20="1")*1+(E20:N20=2)*2+(E20:N20="2")*2)/((COUNTIF(E20:N20,0)+COUNTIF(E20:N20,1)+COUNTIF(E20:N20,2))*2))>=0.5,"Review","Fail"))))))
E21: =IF($B21="","",IF(Checklist!U2="","",Checklist!U2)) | F21: =IF($B21="","",IF(Checklist!U16="","",Checklist!U16)) | G21: =IF($B21="","",IF(Checklist!U25="","",Checklist!U25)) | H21: =IF($B21="","",IF(Checklist!U34="","",Checklist!U34)) | I21: =IF($B21="","",IF(Checklist!U46="","",Checklist!U46)) | J21: =IF($B21="","",IF(Checklist!U59="","",Checklist!U59)) | K21: =IF($B21="","",IF(Checklist!U71="","",Checklist!U71)) | L21: =IF($B21="","",IF(Checklist!U81="","",Checklist!U81)) | M21: =IF($B21="","",IF(Checklist!U91="","",Checklist!U91)) | N21: =IF($B21="","",IF(Checklist!U99="","",Checklist!U99)) | O21: =IF($B21="","",IF((COUNTIF(E21:N21,0)+COUNTIF(E21:N21,1)+COUNTIF(E21:N21,2))=0,"",SUMPRODUCT((E21:N21=1)*1+(E21:N21="1")*1+(E21:N21=2)*2+(E21:N21="2")*2))) | P21: =IF($B21="","",IF(SUMPRODUCT((E21:N21<>"")*1)=0,"Not Run",IF(NOT(SUMPRODUCT((E21:N21<>"")*1)=COLUMNS(E21:N21)),"Incomplete",IF((COUNTIF(E21:N21,0)+COUNTIF(E21:N21,1)+COUNTIF(E21:N21,2))=0,"N/A",IF(AND((SUMPRODUCT((E21:N21=1)*1+(E21:N21="1")*1+(E21:N21=2)*2+(E21:N21="2")*2)/((COUNTIF(E21:N21,0)+COUNTIF(E21:N21,1)+COUNTIF(E21:N21,2))*2))>=0.772727,OR(E21="N/A",E21=1,E21="1",E21=2,E21="2"),OR(G21="N/A",G21=1,G21="1",G21=2,G21="2"),OR(J21="N/A",J21=1,J21="1",J21=2,J21="2")),"Pass",IF((SUMPRODUCT((E21:N21=1)*1+(E21:N21="1")*1+(E21:N21=2)*2+(E21:N21="2")*2)/((COUNTIF(E21:N21,0)+COUNTIF(E21:N21,1)+COUNTIF(E21:N21,2))*2))>=0.5,"Review","Fail"))))))
E22: =IF($B22="","",IF(Checklist!V2="","",Checklist!V2)) | F22: =IF($B22="","",IF(Checklist!V16="","",Checklist!V16)) | G22: =IF($B22="","",IF(Checklist!V25="","",Checklist!V25)) | H22: =IF($B22="","",IF(Checklist!V34="","",Checklist!V34)) | I22: =IF($B22="","",IF(Checklist!V46="","",Checklist!V46)) | J22: =IF($B22="","",IF(Checklist!V59="","",Checklist!V59)) | K22: =IF($B22="","",IF(Checklist!V71="","",Checklist!V71)) | L22: =IF($B22="","",IF(Checklist!V81="","",Checklist!V81)) | M22: =IF($B22="","",IF(Checklist!V91="","",Checklist!V91)) | N22: =IF($B22="","",IF(Checklist!V99="","",Checklist!V99)) | O22: =IF($B22="","",IF((COUNTIF(E22:N22,0)+COUNTIF(E22:N22,1)+COUNTIF(E22:N22,2))=0,"",SUMPRODUCT((E22:N22=1)*1+(E22:N22="1")*1+(E22:N22=2)*2+(E22:N22="2")*2))) | P22: =IF($B22="","",IF(SUMPRODUCT((E22:N22<>"")*1)=0,"Not Run",IF(NOT(SUMPRODUCT((E22:N22<>"")*1)=COLUMNS(E22:N22)),"Incomplete",IF((COUNTIF(E22:N22,0)+COUNTIF(E22:N22,1)+COUNTIF(E22:N22,2))=0,"N/A",IF(AND((SUMPRODUCT((E22:N22=1)*1+(E22:N22="1")*1+(E22:N22=2)*2+(E22:N22="2")*2)/((COUNTIF(E22:N22,0)+COUNTIF(E22:N22,1)+COUNTIF(E22:N22,2))*2))>=0.772727,OR(E22="N/A",E22=1,E22="1",E22=2,E22="2"),OR(G22="N/A",G22=1,G22="1",G22=2,G22="2"),OR(J22="N/A",J22=1,J22="1",J22=2,J22="2")),"Pass",IF((SUMPRODUCT((E22:N22=1)*1+(E22:N22="1")*1+(E22:N22=2)*2+(E22:N22="2")*2)/((COUNTIF(E22:N22,0)+COUNTIF(E22:N22,1)+COUNTIF(E22:N22,2))*2))>=0.5,"Review","Fail"))))))
E23: =IF($B23="","",IF(Checklist!W2="","",Checklist!W2)) | F23: =IF($B23="","",IF(Checklist!W16="","",Checklist!W16)) | G23: =IF($B23="","",IF(Checklist!W25="","",Checklist!W25)) | H23: =IF($B23="","",IF(Checklist!W34="","",Checklist!W34)) | I23: =IF($B23="","",IF(Checklist!W46="","",Checklist!W46)) | J23: =IF($B23="","",IF(Checklist!W59="","",Checklist!W59)) | K23: =IF($B23="","",IF(Checklist!W71="","",Checklist!W71)) | L23: =IF($B23="","",IF(Checklist!W81="","",Checklist!W81)) | M23: =IF($B23="","",IF(Checklist!W91="","",Checklist!W91)) | N23: =IF($B23="","",IF(Checklist!W99="","",Checklist!W99)) | O23: =IF($B23="","",IF((COUNTIF(E23:N23,0)+COUNTIF(E23:N23,1)+COUNTIF(E23:N23,2))=0,"",SUMPRODUCT((E23:N23=1)*1+(E23:N23="1")*1+(E23:N23=2)*2+(E23:N23="2")*2))) | P23: =IF($B23="","",IF(SUMPRODUCT((E23:N23<>"")*1)=0,"Not Run",IF(NOT(SUMPRODUCT((E23:N23<>"")*1)=COLUMNS(E23:N23)),"Incomplete",IF((COUNTIF(E23:N23,0)+COUNTIF(E23:N23,1)+COUNTIF(E23:N23,2))=0,"N/A",IF(AND((SUMPRODUCT((E23:N23=1)*1+(E23:N23="1")*1+(E23:N23=2)*2+(E23:N23="2")*2)/((COUNTIF(E23:N23,0)+COUNTIF(E23:N23,1)+COUNTIF(E23:N23,2))*2))>=0.772727,OR(E23="N/A",E23=1,E23="1",E23=2,E23="2"),OR(G23="N/A",G23=1,G23="1",G23=2,G23="2"),OR(J23="N/A",J23=1,J23="1",J23=2,J23="2")),"Pass",IF((SUMPRODUCT((E23:N23=1)*1+(E23:N23="1")*1+(E23:N23=2)*2+(E23:N23="2")*2)/((COUNTIF(E23:N23,0)+COUNTIF(E23:N23,1)+COUNTIF(E23:N23,2))*2))>=0.5,"Review","Fail"))))))
E24: =IF($B24="","",IF(Checklist!X2="","",Checklist!X2)) | F24: =IF($B24="","",IF(Checklist!X16="","",Checklist!X16)) | G24: =IF($B24="","",IF(Checklist!X25="","",Checklist!X25)) | H24: =IF($B24="","",IF(Checklist!X34="","",Checklist!X34)) | I24: =IF($B24="","",IF(Checklist!X46="","",Checklist!X46)) | J24: =IF($B24="","",IF(Checklist!X59="","",Checklist!X59)) | K24: =IF($B24="","",IF(Checklist!X71="","",Checklist!X71)) | L24: =IF($B24="","",IF(Checklist!X81="","",Checklist!X81)) | M24: =IF($B24="","",IF(Checklist!X91="","",Checklist!X91)) | N24: =IF($B24="","",IF(Checklist!X99="","",Checklist!X99)) | O24: =IF($B24="","",IF((COUNTIF(E24:N24,0)+COUNTIF(E24:N24,1)+COUNTIF(E24:N24,2))=0,"",SUMPRODUCT((E24:N24=1)*1+(E24:N24="1")*1+(E24:N24=2)*2+(E24:N24="2")*2))) | P24: =IF($B24="","",IF(SUMPRODUCT((E24:N24<>"")*1)=0,"Not Run",IF(NOT(SUMPRODUCT((E24:N24<>"")*1)=COLUMNS(E24:N24)),"Incomplete",IF((COUNTIF(E24:N24,0)+COUNTIF(E24:N24,1)+COUNTIF(E24:N24,2))=0,"N/A",IF(AND((SUMPRODUCT((E24:N24=1)*1+(E24:N24="1")*1+(E24:N24=2)*2+(E24:N24="2")*2)/((COUNTIF(E24:N24,0)+COUNTIF(E24:N24,1)+COUNTIF(E24:N24,2))*2))>=0.772727,OR(E24="N/A",E24=1,E24="1",E24=2,E24="2"),OR(G24="N/A",G24=1,G24="1",G24=2,G24="2"),OR(J24="N/A",J24=1,J24="1",J24=2,J24="2")),"Pass",IF((SUMPRODUCT((E24:N24=1)*1+(E24:N24="1")*1+(E24:N24=2)*2+(E24:N24="2")*2)/((COUNTIF(E24:N24,0)+COUNTIF(E24:N24,1)+COUNTIF(E24:N24,2))*2))>=0.5,"Review","Fail"))))))
E25: =IF($B25="","",IF(Checklist!Y2="","",Checklist!Y2)) | F25: =IF($B25="","",IF(Checklist!Y16="","",Checklist!Y16)) | G25: =IF($B25="","",IF(Checklist!Y25="","",Checklist!Y25)) | H25: =IF($B25="","",IF(Checklist!Y34="","",Checklist!Y34)) | I25: =IF($B25="","",IF(Checklist!Y46="","",Checklist!Y46)) | J25: =IF($B25="","",IF(Checklist!Y59="","",Checklist!Y59)) | K25: =IF($B25="","",IF(Checklist!Y71="","",Checklist!Y71)) | L25: =IF($B25="","",IF(Checklist!Y81="","",Checklist!Y81)) | M25: =IF($B25="","",IF(Checklist!Y91="","",Checklist!Y91)) | N25: =IF($B25="","",IF(Checklist!Y99="","",Checklist!Y99)) | O25: =IF($B25="","",IF((COUNTIF(E25:N25,0)+COUNTIF(E25:N25,1)+COUNTIF(E25:N25,2))=0,"",SUMPRODUCT((E25:N25=1)*1+(E25:N25="1")*1+(E25:N25=2)*2+(E25:N25="2")*2))) | P25: =IF($B25="","",IF(SUMPRODUCT((E25:N25<>"")*1)=0,"Not Run",IF(NOT(SUMPRODUCT((E25:N25<>"")*1)=COLUMNS(E25:N25)),"Incomplete",IF((COUNTIF(E25:N25,0)+COUNTIF(E25:N25,1)+COUNTIF(E25:N25,2))=0,"N/A",IF(AND((SUMPRODUCT((E25:N25=1)*1+(E25:N25="1")*1+(E25:N25=2)*2+(E25:N25="2")*2)/((COUNTIF(E25:N25,0)+COUNTIF(E25:N25,1)+COUNTIF(E25:N25,2))*2))>=0.772727,OR(E25="N/A",E25=1,E25="1",E25=2,E25="2"),OR(G25="N/A",G25=1,G25="1",G25=2,G25="2"),OR(J25="N/A",J25=1,J25="1",J25=2,J25="2")),"Pass",IF((SUMPRODUCT((E25:N25=1)*1+(E25:N25="1")*1+(E25:N25=2)*2+(E25:N25="2")*2)/((COUNTIF(E25:N25,0)+COUNTIF(E25:N25,1)+COUNTIF(E25:N25,2))*2))>=0.5,"Review","Fail"))))))
E26: =IF($B26="","",IF(Checklist!Z2="","",Checklist!Z2)) | F26: =IF($B26="","",IF(Checklist!Z16="","",Checklist!Z16)) | G26: =IF($B26="","",IF(Checklist!Z25="","",Checklist!Z25)) | H26: =IF($B26="","",IF(Checklist!Z34="","",Checklist!Z34)) | I26: =IF($B26="","",IF(Checklist!Z46="","",Checklist!Z46)) | J26: =IF($B26="","",IF(Checklist!Z59="","",Checklist!Z59)) | K26: =IF($B26="","",IF(Checklist!Z71="","",Checklist!Z71)) | L26: =IF($B26="","",IF(Checklist!Z81="","",Checklist!Z81)) | M26: =IF($B26="","",IF(Checklist!Z91="","",Checklist!Z91)) | N26: =IF($B26="","",IF(Checklist!Z99="","",Checklist!Z99)) | O26: =IF($B26="","",IF((COUNTIF(E26:N26,0)+COUNTIF(E26:N26,1)+COUNTIF(E26:N26,2))=0,"",SUMPRODUCT((E26:N26=1)*1+(E26:N26="1")*1+(E26:N26=2)*2+(E26:N26="2")*2))) | P26: =IF($B26="","",IF(SUMPRODUCT((E26:N26<>"")*1)=0,"Not Run",IF(NOT(SUMPRODUCT((E26:N26<>"")*1)=COLUMNS(E26:N26)),"Incomplete",IF((COUNTIF(E26:N26,0)+COUNTIF(E26:N26,1)+COUNTIF(E26:N26,2))=0,"N/A",IF(AND((SUMPRODUCT((E26:N26=1)*1+(E26:N26="1")*1+(E26:N26=2)*2+(E26:N26="2")*2)/((COUNTIF(E26:N26,0)+COUNTIF(E26:N26,1)+COUNTIF(E26:N26,2))*2))>=0.772727,OR(E26="N/A",E26=1,E26="1",E26=2,E26="2"),OR(G26="N/A",G26=1,G26="1",G26=2,G26="2"),OR(J26="N/A",J26=1,J26="1",J26=2,J26="2")),"Pass",IF((SUMPRODUCT((E26:N26=1)*1+(E26:N26="1")*1+(E26:N26=2)*2+(E26:N26="2")*2)/((COUNTIF(E26:N26,0)+COUNTIF(E26:N26,1)+COUNTIF(E26:N26,2))*2))>=0.5,"Review","Fail"))))))
E27: =IF($B27="","",IF(Checklist!AA2="","",Checklist!AA2)) | F27: =IF($B27="","",IF(Checklist!AA16="","",Checklist!AA16)) | G27: =IF($B27="","",IF(Checklist!AA25="","",Checklist!AA25)) | H27: =IF($B27="","",IF(Checklist!AA34="","",Checklist!AA34)) | I27: =IF($B27="","",IF(Checklist!AA46="","",Checklist!AA46)) | J27: =IF($B27="","",IF(Checklist!AA59="","",Checklist!AA59)) | K27: =IF($B27="","",IF(Checklist!AA71="","",Checklist!AA71)) | L27: =IF($B27="","",IF(Checklist!AA81="","",Checklist!AA81)) | M27: =IF($B27="","",IF(Checklist!AA91="","",Checklist!AA91)) | N27: =IF($B27="","",IF(Checklist!AA99="","",Checklist!AA99)) | O27: =IF($B27="","",IF((COUNTIF(E27:N27,0)+COUNTIF(E27:N27,1)+COUNTIF(E27:N27,2))=0,"",SUMPRODUCT((E27:N27=1)*1+(E27:N27="1")*1+(E27:N27=2)*2+(E27:N27="2")*2))) | P27: =IF($B27="","",IF(SUMPRODUCT((E27:N27<>"")*1)=0,"Not Run",IF(NOT(SUMPRODUCT((E27:N27<>"")*1)=COLUMNS(E27:N27)),"Incomplete",IF((COUNTIF(E27:N27,0)+COUNTIF(E27:N27,1)+COUNTIF(E27:N27,2))=0,"N/A",IF(AND((SUMPRODUCT((E27:N27=1)*1+(E27:N27="1")*1+(E27:N27=2)*2+(E27:N27="2")*2)/((COUNTIF(E27:N27,0)+COUNTIF(E27:N27,1)+COUNTIF(E27:N27,2))*2))>=0.772727,OR(E27="N/A",E27=1,E27="1",E27=2,E27="2"),OR(G27="N/A",G27=1,G27="1",G27=2,G27="2"),OR(J27="N/A",J27=1,J27="1",J27=2,J27="2")),"Pass",IF((SUMPRODUCT((E27:N27=1)*1+(E27:N27="1")*1+(E27:N27=2)*2+(E27:N27="2")*2)/((COUNTIF(E27:N27,0)+COUNTIF(E27:N27,1)+COUNTIF(E27:N27,2))*2))>=0.5,"Review","Fail"))))))
E28: =IF($B28="","",IF(Checklist!AB2="","",Checklist!AB2)) | F28: =IF($B28="","",IF(Checklist!AB16="","",Checklist!AB16)) | G28: =IF($B28="","",IF(Checklist!AB25="","",Checklist!AB25)) | H28: =IF($B28="","",IF(Checklist!AB34="","",Checklist!AB34)) | I28: =IF($B28="","",IF(Checklist!AB46="","",Checklist!AB46)) | J28: =IF($B28="","",IF(Checklist!AB59="","",Checklist!AB59)) | K28: =IF($B28="","",IF(Checklist!AB71="","",Checklist!AB71)) | L28: =IF($B28="","",IF(Checklist!AB81="","",Checklist!AB81)) | M28: =IF($B28="","",IF(Checklist!AB91="","",Checklist!AB91)) | N28: =IF($B28="","",IF(Checklist!AB99="","",Checklist!AB99)) | O28: =IF($B28="","",IF((COUNTIF(E28:N28,0)+COUNTIF(E28:N28,1)+COUNTIF(E28:N28,2))=0,"",SUMPRODUCT((E28:N28=1)*1+(E28:N28="1")*1+(E28:N28=2)*2+(E28:N28="2")*2))) | P28: =IF($B28="","",IF(SUMPRODUCT((E28:N28<>"")*1)=0,"Not Run",IF(NOT(SUMPRODUCT((E28:N28<>"")*1)=COLUMNS(E28:N28)),"Incomplete",IF((COUNTIF(E28:N28,0)+COUNTIF(E28:N28,1)+COUNTIF(E28:N28,2))=0,"N/A",IF(AND((SUMPRODUCT((E28:N28=1)*1+(E28:N28="1")*1+(E28:N28=2)*2+(E28:N28="2")*2)/((COUNTIF(E28:N28,0)+COUNTIF(E28:N28,1)+COUNTIF(E28:N28,2))*2))>=0.772727,OR(E28="N/A",E28=1,E28="1",E28=2,E28="2"),OR(G28="N/A",G28=1,G28="1",G28=2,G28="2"),OR(J28="N/A",J28=1,J28="1",J28=2,J28="2")),"Pass",IF((SUMPRODUCT((E28:N28=1)*1+(E28:N28="1")*1+(E28:N28=2)*2+(E28:N28="2")*2)/((COUNTIF(E28:N28,0)+COUNTIF(E28:N28,1)+COUNTIF(E28:N28,2))*2))>=0.5,"Review","Fail"))))))
E29: =IF($B29="","",IF(Checklist!AC2="","",Checklist!AC2)) | F29: =IF($B29="","",IF(Checklist!AC16="","",Checklist!AC16)) | G29: =IF($B29="","",IF(Checklist!AC25="","",Checklist!AC25)) | H29: =IF($B29="","",IF(Checklist!AC34="","",Checklist!AC34)) | I29: =IF($B29="","",IF(Checklist!AC46="","",Checklist!AC46)) | J29: =IF($B29="","",IF(Checklist!AC59="","",Checklist!AC59)) | K29: =IF($B29="","",IF(Checklist!AC71="","",Checklist!AC71)) | L29: =IF($B29="","",IF(Checklist!AC81="","",Checklist!AC81)) | M29: =IF($B29="","",IF(Checklist!AC91="","",Checklist!AC91)) | N29: =IF($B29="","",IF(Checklist!AC99="","",Checklist!AC99)) | O29: =IF($B29="","",IF((COUNTIF(E29:N29,0)+COUNTIF(E29:N29,1)+COUNTIF(E29:N29,2))=0,"",SUMPRODUCT((E29:N29=1)*1+(E29:N29="1")*1+(E29:N29=2)*2+(E29:N29="2")*2))) | P29: =IF($B29="","",IF(SUMPRODUCT((E29:N29<>"")*1)=0,"Not Run",IF(NOT(SUMPRODUCT((E29:N29<>"")*1)=COLUMNS(E29:N29)),"Incomplete",IF((COUNTIF(E29:N29,0)+COUNTIF(E29:N29,1)+COUNTIF(E29:N29,2))=0,"N/A",IF(AND((SUMPRODUCT((E29:N29=1)*1+(E29:N29="1")*1+(E29:N29=2)*2+(E29:N29="2")*2)/((COUNTIF(E29:N29,0)+COUNTIF(E29:N29,1)+COUNTIF(E29:N29,2))*2))>=0.772727,OR(E29="N/A",E29=1,E29="1",E29=2,E29="2"),OR(G29="N/A",G29=1,G29="1",G29=2,G29="2"),OR(J29="N/A",J29=1,J29="1",J29=2,J29="2")),"Pass",IF((SUMPRODUCT((E29:N29=1)*1+(E29:N29="1")*1+(E29:N29=2)*2+(E29:N29="2")*2)/((COUNTIF(E29:N29,0)+COUNTIF(E29:N29,1)+COUNTIF(E29:N29,2))*2))>=0.5,"Review","Fail"))))))
E30: =IF($B30="","",IF(Checklist!AD2="","",Checklist!AD2)) | F30: =IF($B30="","",IF(Checklist!AD16="","",Checklist!AD16)) | G30: =IF($B30="","",IF(Checklist!AD25="","",Checklist!AD25)) | H30: =IF($B30="","",IF(Checklist!AD34="","",Checklist!AD34)) | I30: =IF($B30="","",IF(Checklist!AD46="","",Checklist!AD46)) | J30: =IF($B30="","",IF(Checklist!AD59="","",Checklist!AD59)) | K30: =IF($B30="","",IF(Checklist!AD71="","",Checklist!AD71)) | L30: =IF($B30="","",IF(Checklist!AD81="","",Checklist!AD81)) | M30: =IF($B30="","",IF(Checklist!AD91="","",Checklist!AD91)) | N30: =IF($B30="","",IF(Checklist!AD99="","",Checklist!AD99)) | O30: =IF($B30="","",IF((COUNTIF(E30:N30,0)+COUNTIF(E30:N30,1)+COUNTIF(E30:N30,2))=0,"",SUMPRODUCT((E30:N30=1)*1+(E30:N30="1")*1+(E30:N30=2)*2+(E30:N30="2")*2))) | P30: =IF($B30="","",IF(SUMPRODUCT((E30:N30<>"")*1)=0,"Not Run",IF(NOT(SUMPRODUCT((E30:N30<>"")*1)=COLUMNS(E30:N30)),"Incomplete",IF((COUNTIF(E30:N30,0)+COUNTIF(E30:N30,1)+COUNTIF(E30:N30,2))=0,"N/A",IF(AND((SUMPRODUCT((E30:N30=1)*1+(E30:N30="1")*1+(E30:N30=2)*2+(E30:N30="2")*2)/((COUNTIF(E30:N30,0)+COUNTIF(E30:N30,1)+COUNTIF(E30:N30,2))*2))>=0.772727,OR(E30="N/A",E30=1,E30="1",E30=2,E30="2"),OR(G30="N/A",G30=1,G30="1",G30=2,G30="2"),OR(J30="N/A",J30=1,J30="1",J30=2,J30="2")),"Pass",IF((SUMPRODUCT((E30:N30=1)*1+(E30:N30="1")*1+(E30:N30=2)*2+(E30:N30="2")*2)/((COUNTIF(E30:N30,0)+COUNTIF(E30:N30,1)+COUNTIF(E30:N30,2))*2))>=0.5,"Review","Fail"))))))
E31: =IF($B31="","",IF(Checklist!AE2="","",Checklist!AE2)) | F31: =IF($B31="","",IF(Checklist!AE16="","",Checklist!AE16)) | G31: =IF($B31="","",IF(Checklist!AE25="","",Checklist!AE25)) | H31: =IF($B31="","",IF(Checklist!AE34="","",Checklist!AE34)) | I31: =IF($B31="","",IF(Checklist!AE46="","",Checklist!AE46)) | J31: =IF($B31="","",IF(Checklist!AE59="","",Checklist!AE59)) | K31: =IF($B31="","",IF(Checklist!AE71="","",Checklist!AE71)) | L31: =IF($B31="","",IF(Checklist!AE81="","",Checklist!AE81)) | M31: =IF($B31="","",IF(Checklist!AE91="","",Checklist!AE91)) | N31: =IF($B31="","",IF(Checklist!AE99="","",Checklist!AE99)) | O31: =IF($B31="","",IF((COUNTIF(E31:N31,0)+COUNTIF(E31:N31,1)+COUNTIF(E31:N31,2))=0,"",SUMPRODUCT((E31:N31=1)*1+(E31:N31="1")*1+(E31:N31=2)*2+(E31:N31="2")*2))) | P31: =IF($B31="","",IF(SUMPRODUCT((E31:N31<>"")*1)=0,"Not Run",IF(NOT(SUMPRODUCT((E31:N31<>"")*1)=COLUMNS(E31:N31)),"Incomplete",IF((COUNTIF(E31:N31,0)+COUNTIF(E31:N31,1)+COUNTIF(E31:N31,2))=0,"N/A",IF(AND((SUMPRODUCT((E31:N31=1)*1+(E31:N31="1")*1+(E31:N31=2)*2+(E31:N31="2")*2)/((COUNTIF(E31:N31,0)+COUNTIF(E31:N31,1)+COUNTIF(E31:N31,2))*2))>=0.772727,OR(E31="N/A",E31=1,E31="1",E31=2,E31="2"),OR(G31="N/A",G31=1,G31="1",G31=2,G31="2"),OR(J31="N/A",J31=1,J31="1",J31=2,J31="2")),"Pass",IF((SUMPRODUCT((E31:N31=1)*1+(E31:N31="1")*1+(E31:N31=2)*2+(E31:N31="2")*2)/((COUNTIF(E31:N31,0)+COUNTIF(E31:N31,1)+COUNTIF(E31:N31,2))*2))>=0.5,"Review","Fail"))))))
E32: =IF($B32="","",IF(Checklist!AF2="","",Checklist!AF2)) | F32: =IF($B32="","",IF(Checklist!AF16="","",Checklist!AF16)) | G32: =IF($B32="","",IF(Checklist!AF25="","",Checklist!AF25)) | H32: =IF($B32="","",IF(Checklist!AF34="","",Checklist!AF34)) | I32: =IF($B32="","",IF(Checklist!AF46="","",Checklist!AF46)) | J32: =IF($B32="","",IF(Checklist!AF59="","",Checklist!AF59)) | K32: =IF($B32="","",IF(Checklist!AF71="","",Checklist!AF71)) | L32: =IF($B32="","",IF(Checklist!AF81="","",Checklist!AF81)) | M32: =IF($B32="","",IF(Checklist!AF91="","",Checklist!AF91)) | N32: =IF($B32="","",IF(Checklist!AF99="","",Checklist!AF99)) | O32: =IF($B32="","",IF((COUNTIF(E32:N32,0)+COUNTIF(E32:N32,1)+COUNTIF(E32:N32,2))=0,"",SUMPRODUCT((E32:N32=1)*1+(E32:N32="1")*1+(E32:N32=2)*2+(E32:N32="2")*2))) | P32: =IF($B32="","",IF(SUMPRODUCT((E32:N32<>"")*1)=0,"Not Run",IF(NOT(SUMPRODUCT((E32:N32<>"")*1)=COLUMNS(E32:N32)),"Incomplete",IF((COUNTIF(E32:N32,0)+COUNTIF(E32:N32,1)+COUNTIF(E32:N32,2))=0,"N/A",IF(AND((SUMPRODUCT((E32:N32=1)*1+(E32:N32="1")*1+(E32:N32=2)*2+(E32:N32="2")*2)/((COUNTIF(E32:N32,0)+COUNTIF(E32:N32,1)+COUNTIF(E32:N32,2))*2))>=0.772727,OR(E32="N/A",E32=1,E32="1",E32=2,E32="2"),OR(G32="N/A",G32=1,G32="1",G32=2,G32="2"),OR(J32="N/A",J32=1,J32="1",J32=2,J32="2")),"Pass",IF((SUMPRODUCT((E32:N32=1)*1+(E32:N32="1")*1+(E32:N32=2)*2+(E32:N32="2")*2)/((COUNTIF(E32:N32,0)+COUNTIF(E32:N32,1)+COUNTIF(E32:N32,2))*2))>=0.5,"Review","Fail"))))))
E33: =IF($B33="","",IF(Checklist!AG2="","",Checklist!AG2)) | F33: =IF($B33="","",IF(Checklist!AG16="","",Checklist!AG16)) | G33: =IF($B33="","",IF(Checklist!AG25="","",Checklist!AG25)) | H33: =IF($B33="","",IF(Checklist!AG34="","",Checklist!AG34)) | I33: =IF($B33="","",IF(Checklist!AG46="","",Checklist!AG46)) | J33: =IF($B33="","",IF(Checklist!AG59="","",Checklist!AG59)) | K33: =IF($B33="","",IF(Checklist!AG71="","",Checklist!AG71)) | L33: =IF($B33="","",IF(Checklist!AG81="","",Checklist!AG81)) | M33: =IF($B33="","",IF(Checklist!AG91="","",Checklist!AG91)) | N33: =IF($B33="","",IF(Checklist!AG99="","",Checklist!AG99)) | O33: =IF($B33="","",IF((COUNTIF(E33:N33,0)+COUNTIF(E33:N33,1)+COUNTIF(E33:N33,2))=0,"",SUMPRODUCT((E33:N33=1)*1+(E33:N33="1")*1+(E33:N33=2)*2+(E33:N33="2")*2))) | P33: =IF($B33="","",IF(SUMPRODUCT((E33:N33<>"")*1)=0,"Not Run",IF(NOT(SUMPRODUCT((E33:N33<>"")*1)=COLUMNS(E33:N33)),"Incomplete",IF((COUNTIF(E33:N33,0)+COUNTIF(E33:N33,1)+COUNTIF(E33:N33,2))=0,"N/A",IF(AND((SUMPRODUCT((E33:N33=1)*1+(E33:N33="1")*1+(E33:N33=2)*2+(E33:N33="2")*2)/((COUNTIF(E33:N33,0)+COUNTIF(E33:N33,1)+COUNTIF(E33:N33,2))*2))>=0.772727,OR(E33="N/A",E33=1,E33="1",E33=2,E33="2"),OR(G33="N/A",G33=1,G33="1",G33=2,G33="2"),OR(J33="N/A",J33=1,J33="1",J33=2,J33="2")),"Pass",IF((SUMPRODUCT((E33:N33=1)*1+(E33:N33="1")*1+(E33:N33=2)*2+(E33:N33="2")*2)/((COUNTIF(E33:N33,0)+COUNTIF(E33:N33,1)+COUNTIF(E33:N33,2))*2))>=0.5,"Review","Fail"))))))
E34: =IF($B34="","",IF(Checklist!AH2="","",Checklist!AH2)) | F34: =IF($B34="","",IF(Checklist!AH16="","",Checklist!AH16)) | G34: =IF($B34="","",IF(Checklist!AH25="","",Checklist!AH25)) | H34: =IF($B34="","",IF(Checklist!AH34="","",Checklist!AH34)) | I34: =IF($B34="","",IF(Checklist!AH46="","",Checklist!AH46)) | J34: =IF($B34="","",IF(Checklist!AH59="","",Checklist!AH59)) | K34: =IF($B34="","",IF(Checklist!AH71="","",Checklist!AH71)) | L34: =IF($B34="","",IF(Checklist!AH81="","",Checklist!AH81)) | M34: =IF($B34="","",IF(Checklist!AH91="","",Checklist!AH91)) | N34: =IF($B34="","",IF(Checklist!AH99="","",Checklist!AH99)) | O34: =IF($B34="","",IF((COUNTIF(E34:N34,0)+COUNTIF(E34:N34,1)+COUNTIF(E34:N34,2))=0,"",SUMPRODUCT((E34:N34=1)*1+(E34:N34="1")*1+(E34:N34=2)*2+(E34:N34="2")*2))) | P34: =IF($B34="","",IF(SUMPRODUCT((E34:N34<>"")*1)=0,"Not Run",IF(NOT(SUMPRODUCT((E34:N34<>"")*1)=COLUMNS(E34:N34)),"Incomplete",IF((COUNTIF(E34:N34,0)+COUNTIF(E34:N34,1)+COUNTIF(E34:N34,2))=0,"N/A",IF(AND((SUMPRODUCT((E34:N34=1)*1+(E34:N34="1")*1+(E34:N34=2)*2+(E34:N34="2")*2)/((COUNTIF(E34:N34,0)+COUNTIF(E34:N34,1)+COUNTIF(E34:N34,2))*2))>=0.772727,OR(E34="N/A",E34=1,E34="1",E34=2,E34="2"),OR(G34="N/A",G34=1,G34="1",G34=2,G34="2"),OR(J34="N/A",J34=1,J34="1",J34=2,J34="2")),"Pass",IF((SUMPRODUCT((E34:N34=1)*1+(E34:N34="1")*1+(E34:N34=2)*2+(E34:N34="2")*2)/((COUNTIF(E34:N34,0)+COUNTIF(E34:N34,1)+COUNTIF(E34:N34,2))*2))>=0.5,"Review","Fail"))))))
E35: =IF($B35="","",IF(Checklist!AI2="","",Checklist!AI2)) | F35: =IF($B35="","",IF(Checklist!AI16="","",Checklist!AI16)) | G35: =IF($B35="","",IF(Checklist!AI25="","",Checklist!AI25)) | H35: =IF($B35="","",IF(Checklist!AI34="","",Checklist!AI34)) | I35: =IF($B35="","",IF(Checklist!AI46="","",Checklist!AI46)) | J35: =IF($B35="","",IF(Checklist!AI59="","",Checklist!AI59)) | K35: =IF($B35="","",IF(Checklist!AI71="","",Checklist!AI71)) | L35: =IF($B35="","",IF(Checklist!AI81="","",Checklist!AI81)) | M35: =IF($B35="","",IF(Checklist!AI91="","",Checklist!AI91)) | N35: =IF($B35="","",IF(Checklist!AI99="","",Checklist!AI99)) | O35: =IF($B35="","",IF((COUNTIF(E35:N35,0)+COUNTIF(E35:N35,1)+COUNTIF(E35:N35,2))=0,"",SUMPRODUCT((E35:N35=1)*1+(E35:N35="1")*1+(E35:N35=2)*2+(E35:N35="2")*2))) | P35: =IF($B35="","",IF(SUMPRODUCT((E35:N35<>"")*1)=0,"Not Run",IF(NOT(SUMPRODUCT((E35:N35<>"")*1)=COLUMNS(E35:N35)),"Incomplete",IF((COUNTIF(E35:N35,0)+COUNTIF(E35:N35,1)+COUNTIF(E35:N35,2))=0,"N/A",IF(AND((SUMPRODUCT((E35:N35=1)*1+(E35:N35="1")*1+(E35:N35=2)*2+(E35:N35="2")*2)/((COUNTIF(E35:N35,0)+COUNTIF(E35:N35,1)+COUNTIF(E35:N35,2))*2))>=0.772727,OR(E35="N/A",E35=1,E35="1",E35=2,E35="2"),OR(G35="N/A",G35=1,G35="1",G35=2,G35="2"),OR(J35="N/A",J35=1,J35="1",J35=2,J35="2")),"Pass",IF((SUMPRODUCT((E35:N35=1)*1+(E35:N35="1")*1+(E35:N35=2)*2+(E35:N35="2")*2)/((COUNTIF(E35:N35,0)+COUNTIF(E35:N35,1)+COUNTIF(E35:N35,2))*2))>=0.5,"Review","Fail"))))))
E36: =IF($B36="","",IF(Checklist!AJ2="","",Checklist!AJ2)) | F36: =IF($B36="","",IF(Checklist!AJ16="","",Checklist!AJ16)) | G36: =IF($B36="","",IF(Checklist!AJ25="","",Checklist!AJ25)) | H36: =IF($B36="","",IF(Checklist!AJ34="","",Checklist!AJ34)) | I36: =IF($B36="","",IF(Checklist!AJ46="","",Checklist!AJ46)) | J36: =IF($B36="","",IF(Checklist!AJ59="","",Checklist!AJ59)) | K36: =IF($B36="","",IF(Checklist!AJ71="","",Checklist!AJ71)) | L36: =IF($B36="","",IF(Checklist!AJ81="","",Checklist!AJ81)) | M36: =IF($B36="","",IF(Checklist!AJ91="","",Checklist!AJ91)) | N36: =IF($B36="","",IF(Checklist!AJ99="","",Checklist!AJ99)) | O36: =IF($B36="","",IF((COUNTIF(E36:N36,0)+COUNTIF(E36:N36,1)+COUNTIF(E36:N36,2))=0,"",SUMPRODUCT((E36:N36=1)*1+(E36:N36="1")*1+(E36:N36=2)*2+(E36:N36="2")*2))) | P36: =IF($B36="","",IF(SUMPRODUCT((E36:N36<>"")*1)=0,"Not Run",IF(NOT(SUMPRODUCT((E36:N36<>"")*1)=COLUMNS(E36:N36)),"Incomplete",IF((COUNTIF(E36:N36,0)+COUNTIF(E36:N36,1)+COUNTIF(E36:N36,2))=0,"N/A",IF(AND((SUMPRODUCT((E36:N36=1)*1+(E36:N36="1")*1+(E36:N36=2)*2+(E36:N36="2")*2)/((COUNTIF(E36:N36,0)+COUNTIF(E36:N36,1)+COUNTIF(E36:N36,2))*2))>=0.772727,OR(E36="N/A",E36=1,E36="1",E36=2,E36="2"),OR(G36="N/A",G36=1,G36="1",G36=2,G36="2"),OR(J36="N/A",J36=1,J36="1",J36=2,J36="2")),"Pass",IF((SUMPRODUCT((E36:N36=1)*1+(E36:N36="1")*1+(E36:N36=2)*2+(E36:N36="2")*2)/((COUNTIF(E36:N36,0)+COUNTIF(E36:N36,1)+COUNTIF(E36:N36,2))*2))>=0.5,"Review","Fail"))))))
E37: =IF($B37="","",IF(Checklist!AK2="","",Checklist!AK2)) | F37: =IF($B37="","",IF(Checklist!AK16="","",Checklist!AK16)) | G37: =IF($B37="","",IF(Checklist!AK25="","",Checklist!AK25)) | H37: =IF($B37="","",IF(Checklist!AK34="","",Checklist!AK34)) | I37: =IF($B37="","",IF(Checklist!AK46="","",Checklist!AK46)) | J37: =IF($B37="","",IF(Checklist!AK59="","",Checklist!AK59)) | K37: =IF($B37="","",IF(Checklist!AK71="","",Checklist!AK71)) | L37: =IF($B37="","",IF(Checklist!AK81="","",Checklist!AK81)) | M37: =IF($B37="","",IF(Checklist!AK91="","",Checklist!AK91)) | N37: =IF($B37="","",IF(Checklist!AK99="","",Checklist!AK99)) | O37: =IF($B37="","",IF((COUNTIF(E37:N37,0)+COUNTIF(E37:N37,1)+COUNTIF(E37:N37,2))=0,"",SUMPRODUCT((E37:N37=1)*1+(E37:N37="1")*1+(E37:N37=2)*2+(E37:N37="2")*2))) | P37: =IF($B37="","",IF(SUMPRODUCT((E37:N37<>"")*1)=0,"Not Run",IF(NOT(SUMPRODUCT((E37:N37<>"")*1)=COLUMNS(E37:N37)),"Incomplete",IF((COUNTIF(E37:N37,0)+COUNTIF(E37:N37,1)+COUNTIF(E37:N37,2))=0,"N/A",IF(AND((SUMPRODUCT((E37:N37=1)*1+(E37:N37="1")*1+(E37:N37=2)*2+(E37:N37="2")*2)/((COUNTIF(E37:N37,0)+COUNTIF(E37:N37,1)+COUNTIF(E37:N37,2))*2))>=0.772727,OR(E37="N/A",E37=1,E37="1",E37=2,E37="2"),OR(G37="N/A",G37=1,G37="1",G37=2,G37="2"),OR(J37="N/A",J37=1,J37="1",J37=2,J37="2")),"Pass",IF((SUMPRODUCT((E37:N37=1)*1+(E37:N37="1")*1+(E37:N37=2)*2+(E37:N37="2")*2)/((COUNTIF(E37:N37,0)+COUNTIF(E37:N37,1)+COUNTIF(E37:N37,2))*2))>=0.5,"Review","Fail"))))))
E38: =IF($B38="","",IF(Checklist!AL2="","",Checklist!AL2)) | F38: =IF($B38="","",IF(Checklist!AL16="","",Checklist!AL16)) | G38: =IF($B38="","",IF(Checklist!AL25="","",Checklist!AL25)) | H38: =IF($B38="","",IF(Checklist!AL34="","",Checklist!AL34)) | I38: =IF($B38="","",IF(Checklist!AL46="","",Checklist!AL46)) | J38: =IF($B38="","",IF(Checklist!AL59="","",Checklist!AL59)) | K38: =IF($B38="","",IF(Checklist!AL71="","",Checklist!AL71)) | L38: =IF($B38="","",IF(Checklist!AL81="","",Checklist!AL81)) | M38: =IF($B38="","",IF(Checklist!AL91="","",Checklist!AL91)) | N38: =IF($B38="","",IF(Checklist!AL99="","",Checklist!AL99)) | O38: =IF($B38="","",IF((COUNTIF(E38:N38,0)+COUNTIF(E38:N38,1)+COUNTIF(E38:N38,2))=0,"",SUMPRODUCT((E38:N38=1)*1+(E38:N38="1")*1+(E38:N38=2)*2+(E38:N38="2")*2))) | P38: =IF($B38="","",IF(SUMPRODUCT((E38:N38<>"")*1)=0,"Not Run",IF(NOT(SUMPRODUCT((E38:N38<>"")*1)=COLUMNS(E38:N38)),"Incomplete",IF((COUNTIF(E38:N38,0)+COUNTIF(E38:N38,1)+COUNTIF(E38:N38,2))=0,"N/A",IF(AND((SUMPRODUCT((E38:N38=1)*1+(E38:N38="1")*1+(E38:N38=2)*2+(E38:N38="2")*2)/((COUNTIF(E38:N38,0)+COUNTIF(E38:N38,1)+COUNTIF(E38:N38,2))*2))>=0.772727,OR(E38="N/A",E38=1,E38="1",E38=2,E38="2"),OR(G38="N/A",G38=1,G38="1",G38=2,G38="2"),OR(J38="N/A",J38=1,J38="1",J38=2,J38="2")),"Pass",IF((SUMPRODUCT((E38:N38=1)*1+(E38:N38="1")*1+(E38:N38=2)*2+(E38:N38="2")*2)/((COUNTIF(E38:N38,0)+COUNTIF(E38:N38,1)+COUNTIF(E38:N38,2))*2))>=0.5,"Review","Fail"))))))
E39: =IF($B39="","",IF(Checklist!AM2="","",Checklist!AM2)) | F39: =IF($B39="","",IF(Checklist!AM16="","",Checklist!AM16)) | G39: =IF($B39="","",IF(Checklist!AM25="","",Checklist!AM25)) | H39: =IF($B39="","",IF(Checklist!AM34="","",Checklist!AM34)) | I39: =IF($B39="","",IF(Checklist!AM46="","",Checklist!AM46)) | J39: =IF($B39="","",IF(Checklist!AM59="","",Checklist!AM59)) | K39: =IF($B39="","",IF(Checklist!AM71="","",Checklist!AM71)) | L39: =IF($B39="","",IF(Checklist!AM81="","",Checklist!AM81)) | M39: =IF($B39="","",IF(Checklist!AM91="","",Checklist!AM91)) | N39: =IF($B39="","",IF(Checklist!AM99="","",Checklist!AM99)) | O39: =IF($B39="","",IF((COUNTIF(E39:N39,0)+COUNTIF(E39:N39,1)+COUNTIF(E39:N39,2))=0,"",SUMPRODUCT((E39:N39=1)*1+(E39:N39="1")*1+(E39:N39=2)*2+(E39:N39="2")*2))) | P39: =IF($B39="","",IF(SUMPRODUCT((E39:N39<>"")*1)=0,"Not Run",IF(NOT(SUMPRODUCT((E39:N39<>"")*1)=COLUMNS(E39:N39)),"Incomplete",IF((COUNTIF(E39:N39,0)+COUNTIF(E39:N39,1)+COUNTIF(E39:N39,2))=0,"N/A",IF(AND((SUMPRODUCT((E39:N39=1)*1+(E39:N39="1")*1+(E39:N39=2)*2+(E39:N39="2")*2)/((COUNTIF(E39:N39,0)+COUNTIF(E39:N39,1)+COUNTIF(E39:N39,2))*2))>=0.772727,OR(E39="N/A",E39=1,E39="1",E39=2,E39="2"),OR(G39="N/A",G39=1,G39="1",G39=2,G39="2"),OR(J39="N/A",J39=1,J39="1",J39=2,J39="2")),"Pass",IF((SUMPRODUCT((E39:N39=1)*1+(E39:N39="1")*1+(E39:N39=2)*2+(E39:N39="2")*2)/((COUNTIF(E39:N39,0)+COUNTIF(E39:N39,1)+COUNTIF(E39:N39,2))*2))>=0.5,"Review","Fail"))))))
E40: =IF($B40="","",IF(Checklist!AN2="","",Checklist!AN2)) | F40: =IF($B40="","",IF(Checklist!AN16="","",Checklist!AN16)) | G40: =IF($B40="","",IF(Checklist!AN25="","",Checklist!AN25)) | H40: =IF($B40="","",IF(Checklist!AN34="","",Checklist!AN34)) | I40: =IF($B40="","",IF(Checklist!AN46="","",Checklist!AN46)) | J40: =IF($B40="","",IF(Checklist!AN59="","",Checklist!AN59)) | K40: =IF($B40="","",IF(Checklist!AN71="","",Checklist!AN71)) | L40: =IF($B40="","",IF(Checklist!AN81="","",Checklist!AN81)) | M40: =IF($B40="","",IF(Checklist!AN91="","",Checklist!AN91)) | N40: =IF($B40="","",IF(Checklist!AN99="","",Checklist!AN99)) | O40: =IF($B40="","",IF((COUNTIF(E40:N40,0)+COUNTIF(E40:N40,1)+COUNTIF(E40:N40,2))=0,"",SUMPRODUCT((E40:N40=1)*1+(E40:N40="1")*1+(E40:N40=2)*2+(E40:N40="2")*2))) | P40: =IF($B40="","",IF(SUMPRODUCT((E40:N40<>"")*1)=0,"Not Run",IF(NOT(SUMPRODUCT((E40:N40<>"")*1)=COLUMNS(E40:N40)),"Incomplete",IF((COUNTIF(E40:N40,0)+COUNTIF(E40:N40,1)+COUNTIF(E40:N40,2))=0,"N/A",IF(AND((SUMPRODUCT((E40:N40=1)*1+(E40:N40="1")*1+(E40:N40=2)*2+(E40:N40="2")*2)/((COUNTIF(E40:N40,0)+COUNTIF(E40:N40,1)+COUNTIF(E40:N40,2))*2))>=0.772727,OR(E40="N/A",E40=1,E40="1",E40=2,E40="2"),OR(G40="N/A",G40=1,G40="1",G40=2,G40="2"),OR(J40="N/A",J40=1,J40="1",J40=2,J40="2")),"Pass",IF((SUMPRODUCT((E40:N40=1)*1+(E40:N40="1")*1+(E40:N40=2)*2+(E40:N40="2")*2)/((COUNTIF(E40:N40,0)+COUNTIF(E40:N40,1)+COUNTIF(E40:N40,2))*2))>=0.5,"Review","Fail"))))))
...

Sheet Checklist
A1: Category | B1: Checklist Item / Override | C1: =IF('AI Evaluation Sheet'!$B3="","",'AI Evaluation Sheet'!$B3) | D1: =IF('AI Evaluation Sheet'!$B4="","",'AI Evaluation Sheet'!$B4) | E1: =IF('AI Evaluation Sheet'!$B5="","",'AI Evaluation Sheet'!$B5) | F1: =IF('AI Evaluation Sheet'!$B6="","",'AI Evaluation Sheet'!$B6) | G1: =IF('AI Evaluation Sheet'!$B7="","",'AI Evaluation Sheet'!$B7) | H1: =IF('AI Evaluation Sheet'!$B8="","",'AI Evaluation Sheet'!$B8) | I1: =IF('AI Evaluation Sheet'!$B9="","",'AI Evaluation Sheet'!$B9) | J1: =IF('AI Evaluation Sheet'!$B10="","",'AI Evaluation Sheet'!$B10) | K1: =IF('AI Evaluation Sheet'!$B11="","",'AI Evaluation Sheet'!$B11) | L1: =IF('AI Evaluation Sheet'!$B12="","",'AI Evaluation Sheet'!$B12) | M1: =IF('AI Evaluation Sheet'!$B13="","",'AI Evaluation Sheet'!$B13) | N1: =IF('AI Evaluation Sheet'!$B14="","",'AI Evaluation Sheet'!$B14) | O1: =IF('AI Evaluation Sheet'!$B15="","",'AI Evaluation Sheet'!$B15) | P1: =IF('AI Evaluation Sheet'!$B16="","",'AI Evaluation Sheet'!$B16) | Q1: =IF('AI Evaluation Sheet'!$B17="","",'AI Evaluation Sheet'!$B17) | R1: =IF('AI Evaluation Sheet'!$B18="","",'AI Evaluation Sheet'!$B18) | S1: =IF('AI Evaluation Sheet'!$B19="","",'AI Evaluation Sheet'!$B19) | T1: =IF('AI Evaluation Sheet'!$B20="","",'AI Evaluation Sheet'!$B20) | U1: =IF('AI Evaluation Sheet'!$B21="","",'AI Evaluation Sheet'!$B21) | V1: =IF('AI Evaluation Sheet'!$B22="","",'AI Evaluation Sheet'!$B22) | W1: =IF('AI Evaluation Sheet'!$B23="","",'AI Evaluation Sheet'!$B23) | X1: =IF('AI Evaluation Sheet'!$B24="","",'AI Evaluation Sheet'!$B24) | Y1: =IF('AI Evaluation Sheet'!$B25="","",'AI Evaluation Sheet'!$B25) | Z1: =IF('AI Evaluation Sheet'!$B26="","",'AI Evaluation Sheet'!$B26) | AA1: =IF('AI Evaluation Sheet'!$B27="","",'AI Evaluation Sheet'!$B27) | AB1: =IF('AI Evaluation Sheet'!$B28="","",'AI Evaluation Sheet'!$B28) | AC1: =IF('AI Evaluation Sheet'!$B29="","",'AI Evaluation Sheet'!$B29) | AD1: =IF('AI Evaluation Sheet'!$B30="","",'AI Evaluation Sheet'!$B30) | AE1: =IF('AI Evaluation Sheet'!$B31="","",'AI Evaluation Sheet'!$B31) | AF1: =IF('AI Evaluation Sheet'!$B32="","",'AI Evaluation Sheet'!$B32) | AG1: =IF('AI Evaluation Sheet'!$B33="","",'AI Evaluation Sheet'!$B33) | AH1: =IF('AI Evaluation Sheet'!$B34="","",'AI Evaluation Sheet'!$B34) | AI1: =IF('AI Evaluation Sheet'!$B35="","",'AI Evaluation Sheet'!$B35) | AJ1: =IF('AI Evaluation Sheet'!$B36="","",'AI Evaluation Sheet'!$B36) | AK1: =IF('AI Evaluation Sheet'!$B37="","",'AI Evaluation Sheet'!$B37) | AL1: =IF('AI Evaluation Sheet'!$B38="","",'AI Evaluation Sheet'!$B38) | AM1: =IF('AI Evaluation Sheet'!$B39="","",'AI Evaluation Sheet'!$B39) | AN1: =IF('AI Evaluation Sheet'!$B40="","",'AI Evaluation Sheet'!$B40) | AO1: =IF('AI Evaluation Sheet'!$B41="","",'AI Evaluation Sheet'!$B41) | AP1: =IF('AI Evaluation Sheet'!$B42="","",'AI Evaluation Sheet'!$B42) | AQ1: =IF('AI Evaluation Sheet'!$B43="","",'AI Evaluation Sheet'!$B43) | AR1: =IF('AI Evaluation Sheet'!$B44="","",'AI Evaluation Sheet'!$B44) | AS1: =IF('AI Evaluation Sheet'!$B45="","",'AI Evaluation Sheet'!$B45) | AT1: =IF('AI Evaluation Sheet'!$B46="","",'AI Evaluation Sheet'!$B46) | AU1: =IF('AI Evaluation Sheet'!$B47="","",'AI Evaluation Sheet'!$B47) | AV1: =IF('AI Evaluation Sheet'!$B48="","",'AI Evaluation Sheet'!$B48) | AW1: =IF('AI Evaluation Sheet'!$B49="","",'AI Evaluation Sheet'!$B49) | AX1: =IF('AI Evaluation Sheet'!$B50="","",'AI Evaluation Sheet'!$B50) | AY1: =IF('AI Evaluation Sheet'!$B51="","",'AI Evaluation Sheet'!$B51) | AZ1: =IF('AI Evaluation Sheet'!$B52="","",'AI Evaluation Sheet'!$B52) | BA1: =IF('AI Evaluation Sheet'!$B53="","",'AI Evaluation Sheet'!$B53) | BB1: =IF('AI Evaluation Sheet'!$B54="","",'AI Evaluation Sheet'!$B54) | BC1: =IF('AI Evaluation Sheet'!$B55="","",'AI Evaluation Sheet'!$B55)
